<?xml version="1.0" ?>
<!-- =================================================================================== -->
<!-- |    This document was autogenerated by xacro from src/niryo_robot_moveit_interface/config/niryo_ned3pro.urdf.xacro | -->
<!-- |    EDITING THIS FILE BY HAND IS NOT RECOMMENDED                                 | -->
<!-- =================================================================================== -->
<robot name="niryo_ned3pro">
  <!-- Properties -->
  <!-- Links -->
  <link name="world"/>
  <link name="base_link">
    <inertial>
      <origin rpy="0 0 0" xyz="0 0 0.0254"/>
      <mass value="3.70"/>
      <inertia ixx="0.01627370211" ixy="0.0" ixz="0.0" iyy="0.01633345071" iyz="0.0" izz="0.0254462446"/>
    </inertial>
    <visual>
      <origin rpy="0 0 0" xyz="0 0 0"/>
      <geometry>
        <mesh filename="file:///home/ashwanth/ned3pro_simulation/install/niryo_robot_description/share/niryo_robot_description/meshes/ned3pro/collada/base_link.dae"/>
      </geometry>
    </visual>
    <collision>
      <origin rpy="0 0 0" xyz="0 0 0"/>
      <geometry>
        <mesh filename="file:///home/ashwanth/ned3pro_simulation/install/niryo_robot_description/share/niryo_robot_description/meshes/ned3pro/stl/base_link.STL"/>
      </geometry>
    </collision>
  </link>
  <link name="led_ring_link">
    </link>
  <link name="shoulder_link">
    <inertial>
      <origin rpy="0 0 0" xyz="0 0 0.05"/>
      <mass value="1.018"/>
      <inertia ixx="0.00274167942" ixy="0.0" ixz="0.0" iyy="0.00195272317" iyz="0.0" izz="0.00292927208"/>
    </inertial>
    <visual>
      <origin rpy="0 0 0" xyz="0 0 0"/>
      <geometry>
        <mesh filename="file:///home/ashwanth/ned3pro_simulation/install/niryo_robot_description/share/niryo_robot_description/meshes/ned3pro/collada/shoulder_link.dae"/>
      </geometry>
    </visual>
    <collision>
      <origin rpy="0 0 0" xyz="0 0 0"/>
      <geometry>
        <mesh filename="file:///home/ashwanth/ned3pro_simulation/install/niryo_robot_description/share/niryo_robot_description/meshes/ned3pro/stl/shoulder_link.STL"/>
      </geometry>
    </collision>
  </link>
  <link name="arm_link">
    <inertial>
      <origin rpy="0 0 0" xyz="0.115 0 0"/>
      <mass value="1.0"/>
      <inertia ixx="0.00148330442" ixy="0.0" ixz="0.0" iyy="0.00937134365" iyz="0.0" izz="0.00879836087"/>
    </inertial>
    <visual>
      <origin rpy="0 0 0" xyz="0 0 0"/>
      <geometry>
        <mesh filename="file:///home/ashwanth/ned3pro_simulation/install/niryo_robot_description/share/niryo_robot_description/meshes/ned3pro/collada/arm_link.dae"/>
      </geometry>
    </visual>
    <collision>
      <origin rpy="0 0 0" xyz="0 0 0"/>
      <geometry>
        <mesh filename="file:///home/ashwanth/ned3pro_simulation/install/niryo_robot_description/share/niryo_robot_description/meshes/ned3pro/stl/arm_link.STL"/>
      </geometry>
    </collision>
  </link>
  <link name="elbow_link">
    <inertial>
      <origin rpy="0 0 0" xyz="0 0 0"/>
      <mass value="0.350"/>
      <inertia ixx="0.00033180114" ixy="0.0" ixz="0.0" iyy="0.00039973587" iyz="0.0" izz="0.00043216299"/>
    </inertial>
    <visual>
      <origin rpy="0 0 0" xyz="0 0 0"/>
      <geometry>
        <mesh filename="file:///home/ashwanth/ned3pro_simulation/install/niryo_robot_description/share/niryo_robot_description/meshes/ned3pro/collada/elbow_link.dae"/>
      </geometry>
    </visual>
    <collision>
      <origin rpy="0 0 0" xyz="0 0 0"/>
      <geometry>
        <mesh filename="file:///home/ashwanth/ned3pro_simulation/install/niryo_robot_description/share/niryo_robot_description/meshes/ned3pro/stl/elbow_link.STL"/>
      </geometry>
    </collision>
  </link>
  <link name="forearm_link">
    <inertial>
      <origin rpy="0 0 0" xyz="0 0 0.08"/>
      <mass value="0.35538"/>
      <inertia ixx="0.00199244039" ixy="0.0" ixz="0.0" iyy="0.00181907606" iyz="0.0" izz="0.00029473313"/>
    </inertial>
    <visual>
      <origin rpy="0 0 0" xyz="0 0 0"/>
      <geometry>
        <mesh filename="file:///home/ashwanth/ned3pro_simulation/install/niryo_robot_description/share/niryo_robot_description/meshes/ned3pro/collada/forearm_link.dae"/>
      </geometry>
    </visual>
    <collision>
      <origin rpy="0 0 0" xyz="0 0 0"/>
      <geometry>
        <mesh filename="file:///home/ashwanth/ned3pro_simulation/install/niryo_robot_description/share/niryo_robot_description/meshes/ned3pro/stl/forearm_link.STL"/>
      </geometry>
    </collision>
  </link>
  <link name="wrist_link">
    <inertial>
      <origin rpy="0 0 0" xyz="0 0 0"/>
      <mass value="0.19887"/>
      <inertia ixx="0.00006072214" ixy="0.0" ixz="0.0" iyy="0.00018104057" iyz="0.0" izz="0.00019643162"/>
    </inertial>
    <visual>
      <origin rpy="0 0 0" xyz="0 0 0"/>
      <geometry>
        <mesh filename="file:///home/ashwanth/ned3pro_simulation/install/niryo_robot_description/share/niryo_robot_description/meshes/ned3pro/stl/wrist_link.STL"/>
      </geometry>
    </visual>
    <collision>
      <origin rpy="0 0 0" xyz="0 0 0"/>
      <geometry>
        <mesh filename="file:///home/ashwanth/ned3pro_simulation/install/niryo_robot_description/share/niryo_robot_description/meshes/ned3pro/stl/wrist_link.STL"/>
      </geometry>
    </collision>
  </link>
  <link name="hand_link">
    <inertial>
      <origin rpy="0 0 0" xyz="0 0 0"/>
      <mass value="0.01083"/>
      <inertia ixx="0.00000138319" ixy="0.0" ixz="0.0" iyy="0.00000138107" iyz="0.0" izz="0.00000040812"/>
    </inertial>
    <visual>
      <origin rpy="0 0 0" xyz="0 0 0"/>
      <geometry>
        <mesh filename="file:///home/ashwanth/ned3pro_simulation/install/niryo_robot_description/share/niryo_robot_description/meshes/ned3pro/collada/hand_link.dae"/>
      </geometry>
    </visual>
    <collision>
      <origin rpy="0 0 0" xyz="0 0 0"/>
      <geometry>
        <mesh filename="file:///home/ashwanth/ned3pro_simulation/install/niryo_robot_description/share/niryo_robot_description/meshes/ned3pro/stl/wrist_link.STL"/>
      </geometry>
    </collision>
  </link>
  <link name="tool_link">
    <inertial>
      <origin rpy="0 0 0" xyz="0 0 0"/>
      <mass value="0.19887"/>
      <inertia ixx="0.00006072214" ixy="0.0" ixz="0.0" iyy="0.00018104057" iyz="0.0" izz="0.00019643162"/>
    </inertial>
    <visual>
      <origin rpy="0 0 0" xyz="0 0 0"/>
      <geometry>
        <mesh filename="file:///home/ashwanth/ned3pro_simulation/install/niryo_robot_description/share/niryo_robot_description/meshes/ned3pro/stl/scoop_link.STL"/>
      </geometry>
    </visual>
    <collision>
      <origin rpy="0 0 0" xyz="0 0 0"/>
      <geometry>
        <mesh filename="file:///home/ashwanth/ned3pro_simulation/install/niryo_robot_description/share/niryo_robot_description/meshes/ned3pro/stl/scoop_link.STL"/>
      </geometry>
    </collision>
    </link>
  <!-- Joints -->
  <joint name="joint_world" type="fixed">
    <parent link="world"/>
    <child link="base_link"/>
    <origin rpy="0 0 0" xyz="0 0 0"/>
  </joint>
  <joint name="joint_1" type="revolute">
    <origin rpy="0 0 0" xyz="0 0 0.0748"/>
    <parent link="base_link"/>
    <child link="shoulder_link"/>
    <axis xyz="0 0 1"/>
    <limit effort="10.0" lower="-2.96" upper="2.96" velocity="10.0"/>
  </joint>
  <joint name="joint_2" type="revolute">
    <origin rpy="1.570796326795 0 0" xyz="0 0 0.0925"/>
    <parent link="shoulder_link"/>
    <child link="arm_link"/>
    <axis xyz="0 0 1"/>
    <limit effort="10.0" lower="-1.75" upper="0.44" velocity="8.0"/>
  </joint>
  <joint name="joint_3" type="revolute">
    <origin rpy="0 0 0" xyz="0.230 0 0"/>
    <parent link="arm_link"/>
    <child link="elbow_link"/>
    <axis xyz="0 0 1"/>
    <limit effort="7.0" lower="-1.22" upper="1.57" velocity="8.0"/>
  </joint>
  <joint name="joint_4" type="revolute">
    <origin rpy="0 0 0" xyz="0 0 0"/>
    <parent link="elbow_link"/>
    <child link="forearm_link"/>
    <axis xyz="0 0 1"/>
    <limit effort="7.0" lower="-2.09" upper="2.09" velocity="2.0"/>
  </joint>
  <joint name="joint_5" type="revolute">
    <origin rpy="0 0 0" xyz="0 0 0.16"/>
    <parent link="forearm_link"/>
    <child link="wrist_link"/>
    <axis xyz="0 0 1"/>
    <limit effort="6.0" lower="-1.92" upper="1.92" velocity="2.0"/>
  </joint>
  <joint name="joint_6" type="revolute">
    <origin rpy="0 0 0" xyz="0 0 0"/>
    <parent link="wrist_link"/>
    <child link="hand_link"/>
    <axis xyz="0 0 1"/>
    <limit effort="5.0" lower="-3.14" upper="3.14" velocity="2.0"/>
  </joint>
  <joint name="hand_tool_joint" type="fixed">
    <parent link="hand_link"/>
    <child link="tool_link"/>
    <origin rpy="0 0 0" xyz="0 0 0.0275"/>
  </joint>
  <joint name="joint_led_ring" type="fixed">
    <parent link="world"/>
    <child link="led_ring_link"/>
    <origin rpy="0 0 0" xyz="0 0 0.0933"/>
  </joint>
  <ros2_control name="GazeboSimSystem" type="system">
    <hardware>
      <!-- By default, set up controllers for simulation. This won't work on real hardware -->
      <plugin>gz_ros2_control/GazeboSimSystem</plugin>
    </hardware>
    <joint name="joint_1">
      <command_interface name="position"/>
      <state_interface name="position">
        <param name="initial_value">0</param>
      </state_interface>
    </joint>
    <joint name="joint_2">
      <command_interface name="position"/>
      <state_interface name="position">
        <param name="initial_value">0</param>
      </state_interface>
    </joint>
    <joint name="joint_3">
      <command_interface name="position"/>
      <state_interface name="position">
        <param name="initial_value">0</param>
      </state_interface>
    </joint>
    <joint name="joint_4">
      <command_interface name="position"/>
      <state_interface name="position">
        <param name="initial_value">0</param>
      </state_interface>
    </joint>
    <joint name="joint_5">
      <command_interface name="position"/>
      <state_interface name="position">
        <param name="initial_value">0</param>
      </state_interface>
    </joint>
    <joint name="joint_6">
      <command_interface name="position"/>
      <state_interface name="position">
        <param name="initial_value">0</param>
      </state_interface>
    </joint>
  </ros2_control>
</robot>
